Workbook

Sheet ①入力データ
A1: 在庫金額・DOS 予測モデル ― 入力データ
A2: 🟡 黄色 = 手入力 🔵 青色 = 実績（参照のみ） 🟢 緑色 = 自動計算
A4: 【Sell Out 販売金額】 単位：円
A5: 月 | B5: CH1 店舗 | C5: CH2 ROBO | D5: CH3 B2B | E5: 合計
A6: 1月（実績） | B6: 0 | C6: 0 | D6: 0 | E6: =B6+C6+D6
A7: 2月（実績） | B7: 0 | C7: 0 | D7: 0 | E7: =B7+C7+D7
A8: 3月（目標） | B8: 0 | C8: 0 | D8: 0 | E8: =B8+C8+D8
A9: 4月（目標） | B9: 0 | C9: 0 | D9: 0 | E9: =B9+C9+D9
A10: 5月（目標） | B10: 0 | C10: 0 | D10: 0 | E10: =B10+C10+D10
A11: 6月（目標） | B11: 0 | C11: 0 | D11: 0 | E11: =B11+C11+D11
A12: 7月（目標） | B12: 0 | C12: 0 | D12: 0 | E12: =B12+C12+D12
A13: 8月（目標） | B13: 0 | C13: 0 | D13: 0 | E13: =B13+C13+D13
A14: 9月（目標） | B14: 0 | C14: 0 | D14: 0 | E14: =B14+C14+D14
A15: 10月（目標） | B15: 0 | C15: 0 | D15: 0 | E15: =B15+C15+D15
A16: 11月（目標） | B16: 0 | C16: 0 | D16: 0 | E16: =B16+C16+D16
A17: 12月（目標） | B17: 0 | C17: 0 | D17: 0 | E17: =B17+C17+D17
A19: 【仕入入庫金額（채购到货）】 単位：円
A20: 月 | B20: CH1 店舗 | C20: CH2 ROBO | D20: CH3 B2B | E20: 合計
A21: 1月（実績） | B21: 0 | C21: 0 | D21: 0 | E21: =B21+C21+D21
A22: 2月（実績） | B22: 0 | C22: 0 | D22: 0 | E22: =B22+C22+D22
A23: 3月（計画） | B23: 0 | C23: 0 | D23: 0 | E23: =B23+C23+D23
A24: 4月（計画） | B24: 0 | C24: 0 | D24: 0 | E24: =B24+C24+D24
A25: 5月（計画） | B25: 0 | C25: 0 | D25: 0 | E25: =B25+C25+D25
A26: 6月（計画） | B26: 0 | C26: 0 | D26: 0 | E26: =B26+C26+D26
A27: 7月（計画） | B27: 0 | C27: 0 | D27: 0 | E27: =B27+C27+D27
A28: 8月（計画） | B28: 0 | C28: 0 | D28: 0 | E28: =B28+C28+D28
A29: 9月（計画） | B29: 0 | C29: 0 | D29: 0 | E29: =B29+C29+D29
A30: 10月（計画） | B30: 0 | C30: 0 | D30: 0 | E30: =B30+C30+D30
A31: 11月（計画） | B31: 0 | C31: 0 | D31: 0 | E31: =B31+C31+D31
A32: 12月（計画） | B32: 0 | C32: 0 | D32: 0 | E32: =B32+C32+D32
A34: 【月末総在庫 実績】 1月末・2月末のみ入力 単位：円
A35: 月 | B35: CH1 店舗 | C35: CH2 ROBO | D35: CH3 B2B | E35: 合計
A36: 1月末（実績） | B36: 0 | C36: 0 | D36: 0 | E36: =B36+C36+D36
A37: 2月末（実績） | B37: 0 | C37: 0 | D37: 0 | E37: =B37+C37+D37
A40: 【参考】店舗数・ROBO台数（DOS分析の補助用）
A41: 月 | B41: CH1 店舗数（月末） | C41: CH2 ROBO台数（月末） | D41: 備考
A42: 1月 | B42: 0 | C42: 0
A43: 2月 | B43: 0 | C43: 0
A44: 3月 | B44: 0 | C44: 0
A45: 4月 | B45: 0 | C45: 0
...

Sheet ②予測計算
A1: 在庫金額・DOS 月次予測計算シート
A2: 数式は自動設定済み。1月・2月は実績を参照。3月以降は入力データシートの計画値から自動計算。
A3: 指標 | B3: 1月 | C3: 2月 | D3: 3月 | E3: 4月 | F3: 5月 | G3: 6月 | H3: 7月 | I3: 8月 | J3: 9月 | K3: 10月 | L3: 11月 | M3: 12月
A5: CH1 店舗
A6: Sell Out 販売金額 | B6: ='①入力データ'!B6 | C6: ='①入力データ'!B7 | D6: ='①入力データ'!B8 | E6: ='①入力データ'!B9 | F6: ='①入力データ'!B10 | G6: ='①入力データ'!B11 | H6: ='①入力データ'!B12 | I6: ='①入力データ'!B13 | J6: ='①入力データ'!B14 | K6: ='①入力データ'!B15 | L6: ='①入力データ'!B16 | M6: ='①入力データ'!B17
A7: 仕入入庫金額 | B7: ='①入力データ'!B21 | C7: ='①入力データ'!B22 | D7: ='①入力データ'!B23 | E7: ='①入力データ'!B24 | F7: ='①入力データ'!B25 | G7: ='①入力データ'!B26 | H7: ='①入力データ'!B27 | I7: ='①入力データ'!B28 | J7: ='①入力データ'!B29 | K7: ='①入力データ'!B30 | L7: ='①入力データ'!B31 | M7: ='①入力データ'!B32
A8: 月末在庫金額 | B8: ='①入力データ'!B36 | C8: ='①入力データ'!B37 | D8: =C8+D7-D6 | E8: =D8+E7-E6 | F8: =E8+F7-F6 | G8: =F8+G7-G6 | H8: =G8+H7-H6 | I8: =H8+I7-I6 | J8: =I8+J7-J6 | K8: =J8+K7-K6 | ... M8: =L8+M7-M6
A9: 翌月 日別Sell Out | B9: ='①入力データ'!B7/28 | C9: ='①入力データ'!B8/31 | D9: ='①入力データ'!B9/30 | E9: ='①入力データ'!B10/31 | F9: ='①入力データ'!B11/30 | G9: ='①入力データ'!B12/31 | H9: ='①入力データ'!B13/31 | I9: ='①入力データ'!B14/30 | J9: ='①入力データ'!B15/31 | K9: ='①入力データ'!B16/30 | L9: ='①入力データ'!B17/31 | M9: ='①入力データ'!B17/31
A10: DOS（日） | B10: =IF(B9>0, B8/B9, 0) | C10: =IF(C9>0, C8/C9, 0) | D10: =IF(D9>0, D8/D9, 0) | E10: =IF(E9>0, E8/E9, 0) | F10: =IF(F9>0, F8/F9, 0) | G10: =IF(G9>0, G8/G9, 0) | H10: =IF(H9>0, H8/H9, 0) | I10: =IF(I9>0, I8/I9, 0) | ... M10: =IF(M9>0, M8/M9, 0)
A13: CH2 ROBO
A14: Sell Out 販売金額 | B14: ='①入力データ'!C6 | C14: ='①入力データ'!C7 | D14: ='①入力データ'!C8 | E14: ='①入力データ'!C9 | F14: ='①入力データ'!C10 | G14: ='①入力データ'!C11 | H14: ='①入力データ'!C12 | I14: ='①入力データ'!C13 | J14: ='①入力データ'!C14 | K14: ='①入力データ'!C15 | L14: ='①入力データ'!C16 | M14: ='①入力データ'!C17
A15: 仕入入庫金額 | B15: ='①入力データ'!C21 | C15: ='①入力データ'!C22 | D15: ='①入力データ'!C23 | E15: ='①入力データ'!C24 | F15: ='①入力データ'!C25 | G15: ='①入力データ'!C26 | H15: ='①入力データ'!C27 | I15: ='①入力データ'!C28 | J15: ='①入力データ'!C29 | K15: ='①入力データ'!C30 | L15: ='①入力データ'!C31 | M15: ='①入力データ'!C32
A16: 月末在庫金額 | B16: ='①入力データ'!C36 | C16: ='①入力データ'!C37 | D16: =C16+D15-D14 | E16: =D16+E15-E14 | F16: =E16+F15-F14 | G16: =F16+G15-G14 | H16: =G16+H15-H14 | I16: =H16+I15-I14 | J16: =I16+J15-J14 | K16: =J16+K15-K14 | ... M16: =L16+M15-M14
A17: 翌月 日別Sell Out | B17: ='①入力データ'!C7/28 | C17: ='①入力データ'!C8/31 | D17: ='①入力データ'!C9/30 | E17: ='①入力データ'!C10/31 | F17: ='①入力データ'!C11/30 | G17: ='①入力データ'!C12/31 | H17: ='①入力データ'!C13/31 | I17: ='①入力データ'!C14/30 | J17: ='①入力データ'!C15/31 | K17: ='①入力データ'!C16/30 | L17: ='①入力データ'!C17/31 | M17: ='①入力データ'!C17/31
A18: DOS（日） | B18: =IF(B17>0, B16/B17, 0) | C18: =IF(C17>0, C16/C17, 0) | D18: =IF(D17>0, D16/D17, 0) | E18: =IF(E17>0, E16/E17, 0) | F18: =IF(F17>0, F16/F17, 0) | G18: =IF(G17>0, G16/G17, 0) | H18: =IF(H17>0, H16/H17, 0) | I18: =IF(I17>0, I16/I17, 0) | ... M18: =IF(M17>0, M16/M17, 0)
A21: CH3 B2B
A22: Sell Out 販売金額 | B22: ='①入力データ'!D6 | C22: ='①入力データ'!D7 | D22: ='①入力データ'!D8 | E22: ='①入力データ'!D9 | F22: ='①入力データ'!D10 | G22: ='①入力データ'!D11 | H22: ='①入力データ'!D12 | I22: ='①入力データ'!D13 | J22: ='①入力データ'!D14 | K22: ='①入力データ'!D15 | L22: ='①入力データ'!D16 | M22: ='①入力データ'!D17
A23: 仕入入庫金額 | B23: ='①入力データ'!D21 | C23: ='①入力データ'!D22 | D23: ='①入力データ'!D23 | E23: ='①入力データ'!D24 | F23: ='①入力データ'!D25 | G23: ='①入力データ'!D26 | H23: ='①入力データ'!D27 | I23: ='①入力データ'!D28 | J23: ='①入力データ'!D29 | K23: ='①入力データ'!D30 | L23: ='①入力データ'!D31 | M23: ='①入力データ'!D32
A24: 月末在庫金額 | B24: ='①入力データ'!D36 | C24: ='①入力データ'!D37 | D24: =C24+D23-D22 | E24: =D24+E23-E22 | F24: =E24+F23-F22 | G24: =F24+G23-G22 | H24: =G24+H23-H22 | I24: =H24+I23-I22 | J24: =I24+J23-J22 | K24: =J24+K23-K22 | ... M24: =L24+M23-M22
A25: 翌月 日別Sell Out | B25: ='①入力データ'!D7/28 | C25: ='①入力データ'!D8/31 | D25: ='①入力データ'!D9/30 | E25: ='①入力データ'!D10/31 | F25: ='①入力データ'!D11/30 | G25: ='①入力データ'!D12/31 | H25: ='①入力データ'!D13/31 | I25: ='①入力データ'!D14/30 | J25: ='①入力データ'!D15/31 | K25: ='①入力データ'!D16/30 | L25: ='①入力データ'!D17/31 | M25: ='①入力データ'!D17/31
A26: DOS（日） | B26: =IF(B25>0, B24/B25, 0) | C26: =IF(C25>0, C24/C25, 0) | D26: =IF(D25>0, D24/D25, 0) | E26: =IF(E25>0, E24/E25, 0) | F26: =IF(F25>0, F24/F25, 0) | G26: =IF(G25>0, G24/G25, 0) | H26: =IF(H25>0, H24/H25, 0) | I26: =IF(I25>0, I24/I25, 0) | ... M26: =IF(M25>0, M24/M25, 0)
A29: 合計（全チャネル）
A30: 合計 Sell Out 販売 | B30: =B6+B14+B22 | C30: =C6+C14+C22 | D30: =D6+D14+D22 | E30: =E6+E14+E22 | F30: =F6+F14+F22 | G30: =G6+G14+G22 | H30: =H6+H14+H22 | I30: =I6+I14+I22 | ... M30: =M6+M14+M22
A31: 合計 仕入入庫 | B31: =B7+B15+B23 | C31: =C7+C15+C23 | D31: =D7+D15+D23 | E31: =E7+E15+E23 | F31: =F7+F15+F23 | G31: =G7+G15+G23 | H31: =H7+H15+H23 | I31: =I7+I15+I23 | ... M31: =M7+M15+M23
A32: 合計 月末在庫 | B32: =B8+B16+B24 | C32: =C8+C16+C24 | D32: =D8+D16+D24 | E32: =E8+E16+E24 | F32: =F8+F16+F24 | G32: =G8+G16+G24 | H32: =H8+H16+H24 | I32: =I8+I16+I24 | ... M32: =M8+M16+M24
A33: 翌月 日別 合計Sell Out | B33: ='①入力データ'!E7/28 | C33: ='①入力データ'!E8/31 | D33: ='①入力データ'!E9/30 | E33: ='①入力データ'!E10/31 | F33: ='①入力データ'!E11/30 | G33: ='①入力データ'!E12/31 | H33: ='①入力データ'!E13/31 | I33: ='①入力データ'!E14/30 | J33: ='①入力データ'!E15/31 | K33: ='①入力データ'!E16/30 | L33: ='①入力データ'!E17/31 | M33: ='①入力データ'!E17/31
A34: 合計 DOS（日） | B34: =IF(B33>0,B32/B33,0) | C34: =IF(C33>0,C32/C33,0) | D34: =IF(D33>0,D32/D33,0) | E34: =IF(E33>0,E32/E33,0) | F34: =IF(F33>0,F32/F33,0) | G34: =IF(G33>0,G32/G33,0) | H34: =IF(H33>0,H32/H33,0) | I34: =IF(I33>0,I32/I33,0) | ... M34: =IF(M33>0,M32/M33,0)

Sheet ③サマリ
A1: サマリダッシュボード ― 月次在庫金額・DOS 推移
A3: 指標 | B3: 1月 | C3: 2月 | D3: 3月 | E3: 4月 | F3: 5月 | G3: 6月 | H3: 7月 | I3: 8月 | J3: 9月 | K3: 10月 | L3: 11月 | M3: 12月
A4: ─── Sell Out 販売 ───
A5: CH1 店舗 | B5: ='②予測計算'!B6 | C5: ='②予測計算'!C6 | D5: ='②予測計算'!D6 | E5: ='②予測計算'!E6 | F5: ='②予測計算'!F6 | G5: ='②予測計算'!G6 | H5: ='②予測計算'!H6 | I5: ='②予測計算'!I6 | ... M5: ='②予測計算'!M6
A6: CH2 ROBO | B6: ='②予測計算'!B14 | C6: ='②予測計算'!C14 | D6: ='②予測計算'!D14 | E6: ='②予測計算'!E14 | F6: ='②予測計算'!F14 | G6: ='②予測計算'!G14 | H6: ='②予測計算'!H14 | I6: ='②予測計算'!I14 | ... M6: ='②予測計算'!M14
A7: CH3 B2B | B7: ='②予測計算'!B22 | C7: ='②予測計算'!C22 | D7: ='②予測計算'!D22 | E7: ='②予測計算'!E22 | F7: ='②予測計算'!F22 | G7: ='②予測計算'!G22 | H7: ='②予測計算'!H22 | I7: ='②予測計算'!I22 | ... M7: ='②予測計算'!M22
A8: 合計 Sell Out | B8: ='②予測計算'!B30 | C8: ='②予測計算'!C30 | D8: ='②予測計算'!D30 | E8: ='②予測計算'!E30 | F8: ='②予測計算'!F30 | G8: ='②予測計算'!G30 | H8: ='②予測計算'!H30 | I8: ='②予測計算'!I30 | ... M8: ='②予測計算'!M30
A9: ─── 月末在庫金額 ───
A10: CH1 店舗 | B10: ='②予測計算'!B8 | C10: ='②予測計算'!C8 | D10: ='②予測計算'!D8 | E10: ='②予測計算'!E8 | F10: ='②予測計算'!F8 | G10: ='②予測計算'!G8 | H10: ='②予測計算'!H8 | I10: ='②予測計算'!I8 | ... M10: ='②予測計算'!M8
A11: CH2 ROBO | B11: ='②予測計算'!B16 | C11: ='②予測計算'!C16 | D11: ='②予測計算'!D16 | E11: ='②予測計算'!E16 | F11: ='②予測計算'!F16 | G11: ='②予測計算'!G16 | H11: ='②予測計算'!H16 | I11: ='②予測計算'!I16 | ... M11: ='②予測計算'!M16
A12: CH3 B2B | B12: ='②予測計算'!B24 | C12: ='②予測計算'!C24 | D12: ='②予測計算'!D24 | E12: ='②予測計算'!E24 | F12: ='②予測計算'!F24 | G12: ='②予測計算'!G24 | H12: ='②予測計算'!H24 | I12: ='②予測計算'!I24 | ... M12: ='②予測計算'!M24
A13: 合計 在庫 | B13: ='②予測計算'!B32 | C13: ='②予測計算'!C32 | D13: ='②予測計算'!D32 | E13: ='②予測計算'!E32 | F13: ='②予測計算'!F32 | G13: ='②予測計算'!G32 | H13: ='②予測計算'!H32 | I13: ='②予測計算'!I32 | ... M13: ='②予測計算'!M32
A14: ─── DOS（日）───
A15: CH1 DOS | B15: ='②予測計算'!B10 | C15: ='②予測計算'!C10 | D15: ='②予測計算'!D10 | E15: ='②予測計算'!E10 | F15: ='②予測計算'!F10 | G15: ='②予測計算'!G10 | H15: ='②予測計算'!H10 | I15: ='②予測計算'!I10 | ... M15: ='②予測計算'!M10
A16: CH2 DOS | B16: ='②予測計算'!B18 | C16: ='②予測計算'!C18 | D16: ='②予測計算'!D18 | E16: ='②予測計算'!E18 | F16: ='②予測計算'!F18 | G16: ='②予測計算'!G18 | H16: ='②予測計算'!H18 | I16: ='②予測計算'!I18 | ... M16: ='②予測計算'!M18
A17: CH3 DOS | B17: ='②予測計算'!B26 | C17: ='②予測計算'!C26 | D17: ='②予測計算'!D26 | E17: ='②予測計算'!E26 | F17: ='②予測計算'!F26 | G17: ='②予測計算'!G26 | H17: ='②予測計算'!H26 | I17: ='②予測計算'!I26 | ... M17: ='②予測計算'!M26
A18: 合計 DOS | B18: ='②予測計算'!B34 | C18: ='②予測計算'!C34 | D18: ='②予測計算'!D34 | E18: ='②予測計算'!E34 | F18: ='②予測計算'!F34 | G18: ='②予測計算'!G34 | H18: ='②予測計算'!H34 | I18: ='②予測計算'!I34 | ... M18: ='②予測計算'!M34
