Workbook

Sheet ①入力データ
A1: 在庫金額・DOS予測モデル ― 入力データシート
A2: 🟡 黄色セル = 手入力 | 🟢 緑色セル = 自動計算（触らない） | ※1月・2月は実績値を入力
A4: 【販売データ】 単位：円
A5: 月 | B5: CH1 店舗 | C5: CH2 ROBO | D5: CH3 B2B | E5: 合計
A6: 1月（実績） | B6: 0 | C6: 0 | D6: 0 | E6: =B6+C6+D6
A7: 2月（実績） | B7: 0 | C7: 0 | D7: 0 | E7: =B7+C7+D7
A8: 3月（目標） | B8: 0 | C8: 0 | D8: 0 | E8: =B8+C8+D8
A9: 4月（目標） | B9: 0 | C9: 0 | D9: 0 | E9: =B9+C9+D9
A10: 5月（目標） | B10: 0 | C10: 0 | D10: 0 | E10: =B10+C10+D10
A11: 6月（目標） | B11: 0 | C11: 0 | D11: 0 | E11: =B11+C11+D11
A12: 7月（目標） | B12: 0 | C12: 0 | D12: 0 | E12: =B12+C12+D12
A13: 8月（目標） | B13: 0 | C13: 0 | D13: 0 | E13: =B13+C13+D13
A14: 9月（目標） | B14: 0 | C14: 0 | D14: 0 | E14: =B14+C14+D14
A15: 10月（目標） | B15: 0 | C15: 0 | D15: 0 | E15: =B15+C15+D15
A16: 11月（目標） | B16: 0 | C16: 0 | D16: 0 | E16: =B16+C16+D16
A17: 12月（目標） | B17: 0 | C17: 0 | D17: 0 | E17: =B17+C17+D17
A19: 【仕入計画】 単位：円
A20: 月 | B20: CH1 店舗 | C20: CH2 ROBO | D20: CH3 B2B | E20: 合計
A21: 1月 | B21: 0 | C21: 0 | D21: 0 | E21: =B21+C21+D21
A22: 2月 | B22: 0 | C22: 0 | D22: 0 | E22: =B22+C22+D22
A23: 3月 | B23: 0 | C23: 0 | D23: 0 | E23: =B23+C23+D23
A24: 4月 | B24: 0 | C24: 0 | D24: 0 | E24: =B24+C24+D24
A25: 5月 | B25: 0 | C25: 0 | D25: 0 | E25: =B25+C25+D25
A26: 6月 | B26: 0 | C26: 0 | D26: 0 | E26: =B26+C26+D26
A27: 7月 | B27: 0 | C27: 0 | D27: 0 | E27: =B27+C27+D27
A28: 8月 | B28: 0 | C28: 0 | D28: 0 | E28: =B28+C28+D28
A29: 9月 | B29: 0 | C29: 0 | D29: 0 | E29: =B29+C29+D29
A30: 10月 | B30: 0 | C30: 0 | D30: 0 | E30: =B30+C30+D30
A31: 11月 | B31: 0 | C31: 0 | D31: 0 | E31: =B31+C31+D31
A32: 12月 | B32: 0 | C32: 0 | D32: 0 | E32: =B32+C32+D32
A34: 【店舗数・ROBO台数】
A35: 月 | B35: 店舗 月初数 | C35: 新規 OPEN | D35: 閉店 CLOSE | E35: 店舗 月末数 | G35: 月 | H35: ROBO 月初台数 | I35: 新規 追加台数 | J35: ROBO 月末台数
A36: 1月 | B36: 0 | C36: 0 | D36: 0 | E36: =B36+C36-D36 | G36: 1月 | H36: 0 | I36: 0 | J36: =H36+I36
A37: 2月 | B37: 0 | C37: 0 | D37: 0 | E37: =B37+C37-D37 | G37: 2月 | H37: 0 | I37: 0 | J37: =H37+I37
A38: 3月 | B38: 0 | C38: 0 | D38: 0 | E38: =B38+C38-D38 | G38: 3月 | H38: 0 | I38: 0 | J38: =H38+I38
A39: 4月 | B39: 0 | C39: 0 | D39: 0 | E39: =B39+C39-D39 | G39: 4月 | H39: 0 | I39: 0 | J39: =H39+I39
A40: 5月 | B40: 0 | C40: 0 | D40: 0 | E40: =B40+C40-D40 | G40: 5月 | H40: 0 | I40: 0 | J40: =H40+I40
A41: 6月 | B41: 0 | C41: 0 | D41: 0 | E41: =B41+C41-D41 | G41: 6月 | H41: 0 | I41: 0 | J41: =H41+I41
A42: 7月 | B42: 0 | C42: 0 | D42: 0 | E42: =B42+C42-D42 | G42: 7月 | H42: 0 | I42: 0 | J42: =H42+I42
A43: 8月 | B43: 0 | C43: 0 | D43: 0 | E43: =B43+C43-D43 | G43: 8月 | H43: 0 | I43: 0 | J43: =H43+I43
...

Sheet ②CH1_店舗
A1: 在庫・DOS予測 ― CH1 店舗
A2: ※ 月初在庫：1月は入力データシートの実績値を参照 2月以降は前月末在庫を自動引継ぎ
A3: 月 | B3: 当月日数 | C3: 月初在庫 | D3: 仕入 | E3: 新規OPEN調整 | F3: 閉店調整 | G3: 当月売上 | H3: 月末在庫 | I3: 翌月日販 | J3: DOS（日）
A4: 1月 | B4: 31 | C4: ='①入力データ'!B50 | D4: ='①入力データ'!B21 | E4: ='①入力データ'!C36*'①入力データ'!B56 | F4: =-'①入力データ'!D36*(IF('①入力データ'!B36>0, C4/'①入力データ'!B36, 0)) | G4: ='①入力データ'!B6 | H4: =C4+D4+E4+F4-G4 | I4: ='①入力データ'!B7/28 | J4: =IF(I4>0, H4/I4, 0)
A5: 2月 | B5: 28 | C5: ='①入力データ'!B51 | D5: ='①入力データ'!B22 | E5: ='①入力データ'!C37*'①入力データ'!B56 | F5: =-'①入力データ'!D37*(IF('①入力データ'!B37>0, C5/'①入力データ'!B37, 0)) | G5: ='①入力データ'!B7 | H5: =C5+D5+E5+F5-G5 | I5: ='①入力データ'!B8/31 | J5: =IF(I5>0, H5/I5, 0)
A6: 3月 | B6: 31 | C6: =H5 | D6: ='①入力データ'!B23 | E6: ='①入力データ'!C38*'①入力データ'!B56 | F6: =-'①入力データ'!D38*(IF('①入力データ'!B38>0, C6/'①入力データ'!B38, 0)) | G6: ='①入力データ'!B8 | H6: =C6+D6+E6+F6-G6 | I6: ='①入力データ'!B9/30 | J6: =IF(I6>0, H6/I6, 0)
A7: 4月 | B7: 30 | C7: =H6 | D7: ='①入力データ'!B24 | E7: ='①入力データ'!C39*'①入力データ'!B56 | F7: =-'①入力データ'!D39*(IF('①入力データ'!B39>0, C7/'①入力データ'!B39, 0)) | G7: ='①入力データ'!B9 | H7: =C7+D7+E7+F7-G7 | I7: ='①入力データ'!B10/31 | J7: =IF(I7>0, H7/I7, 0)
A8: 5月 | B8: 31 | C8: =H7 | D8: ='①入力データ'!B25 | E8: ='①入力データ'!C40*'①入力データ'!B56 | F8: =-'①入力データ'!D40*(IF('①入力データ'!B40>0, C8/'①入力データ'!B40, 0)) | G8: ='①入力データ'!B10 | H8: =C8+D8+E8+F8-G8 | I8: ='①入力データ'!B11/30 | J8: =IF(I8>0, H8/I8, 0)
A9: 6月 | B9: 30 | C9: =H8 | D9: ='①入力データ'!B26 | E9: ='①入力データ'!C41*'①入力データ'!B56 | F9: =-'①入力データ'!D41*(IF('①入力データ'!B41>0, C9/'①入力データ'!B41, 0)) | G9: ='①入力データ'!B11 | H9: =C9+D9+E9+F9-G9 | I9: ='①入力データ'!B12/31 | J9: =IF(I9>0, H9/I9, 0)
A10: 7月 | B10: 31 | C10: =H9 | D10: ='①入力データ'!B27 | E10: ='①入力データ'!C42*'①入力データ'!B56 | F10: =-'①入力データ'!D42*(IF('①入力データ'!B42>0, C10/'①入力データ'!B42, 0)) | G10: ='①入力データ'!B12 | H10: =C10+D10+E10+F10-G10 | I10: ='①入力データ'!B13/31 | J10: =IF(I10>0, H10/I10, 0)
A11: 8月 | B11: 31 | C11: =H10 | D11: ='①入力データ'!B28 | E11: ='①入力データ'!C43*'①入力データ'!B56 | F11: =-'①入力データ'!D43*(IF('①入力データ'!B43>0, C11/'①入力データ'!B43, 0)) | G11: ='①入力データ'!B13 | H11: =C11+D11+E11+F11-G11 | I11: ='①入力データ'!B14/30 | J11: =IF(I11>0, H11/I11, 0)
A12: 9月 | B12: 30 | C12: =H11 | D12: ='①入力データ'!B29 | E12: ='①入力データ'!C44*'①入力データ'!B56 | F12: =-'①入力データ'!D44*(IF('①入力データ'!B44>0, C12/'①入力データ'!B44, 0)) | G12: ='①入力データ'!B14 | H12: =C12+D12+E12+F12-G12 | I12: ='①入力データ'!B15/31 | J12: =IF(I12>0, H12/I12, 0)
A13: 10月 | B13: 31 | C13: =H12 | D13: ='①入力データ'!B30 | E13: ='①入力データ'!C45*'①入力データ'!B56 | F13: =-'①入力データ'!D45*(IF('①入力データ'!B45>0, C13/'①入力データ'!B45, 0)) | G13: ='①入力データ'!B15 | H13: =C13+D13+E13+F13-G13 | I13: ='①入力データ'!B16/30 | J13: =IF(I13>0, H13/I13, 0)
A14: 11月 | B14: 30 | C14: =H13 | D14: ='①入力データ'!B31 | E14: ='①入力データ'!C46*'①入力データ'!B56 | F14: =-'①入力データ'!D46*(IF('①入力データ'!B46>0, C14/'①入力データ'!B46, 0)) | G14: ='①入力データ'!B16 | H14: =C14+D14+E14+F14-G14 | I14: ='①入力データ'!B17/31 | J14: =IF(I14>0, H14/I14, 0)
A15: 12月 | B15: 31 | C15: =H14 | D15: ='①入力データ'!B32 | E15: ='①入力データ'!C47*'①入力データ'!B56 | F15: =-'①入力データ'!D47*(IF('①入力データ'!B47>0, C15/'①入力データ'!B47, 0)) | G15: ='①入力データ'!B17 | H15: =C15+D15+E15+F15-G15 | I15: ='①入力データ'!B17/31 | J15: =IF(I15>0, H15/I15, 0)

Sheet ③CH2_ROBO
A1: 在庫・DOS予測 ― CH2 ROBO
A2: ※ 月初在庫：1月は入力データシートの実績値を参照 2月以降は前月末在庫を自動引継ぎ
A3: 月 | B3: 当月日数 | C3: 月初在庫 | D3: 仕入 | E3: 新規ROBO調整 | F3: （予備） | G3: 当月売上 | H3: 月末在庫 | I3: 翌月日販 | J3: DOS（日）
A4: 1月 | B4: 31 | C4: ='①入力データ'!B52 | D4: ='①入力データ'!C21 | E4: ='①入力データ'!I36*'①入力データ'!B57 | F4: ― | G4: ='①入力データ'!C6 | H4: =C4+D4+E4-G4 | I4: ='①入力データ'!C7/28 | J4: =IF(I4>0, H4/I4, 0)
A5: 2月 | B5: 28 | C5: ='①入力データ'!B53 | D5: ='①入力データ'!C22 | E5: ='①入力データ'!I37*'①入力データ'!B57 | F5: ― | G5: ='①入力データ'!C7 | H5: =C5+D5+E5-G5 | I5: ='①入力データ'!C8/31 | J5: =IF(I5>0, H5/I5, 0)
A6: 3月 | B6: 31 | C6: =H5 | D6: ='①入力データ'!C23 | E6: ='①入力データ'!I38*'①入力データ'!B57 | F6: ― | G6: ='①入力データ'!C8 | H6: =C6+D6+E6-G6 | I6: ='①入力データ'!C9/30 | J6: =IF(I6>0, H6/I6, 0)
A7: 4月 | B7: 30 | C7: =H6 | D7: ='①入力データ'!C24 | E7: ='①入力データ'!I39*'①入力データ'!B57 | F7: ― | G7: ='①入力データ'!C9 | H7: =C7+D7+E7-G7 | I7: ='①入力データ'!C10/31 | J7: =IF(I7>0, H7/I7, 0)
A8: 5月 | B8: 31 | C8: =H7 | D8: ='①入力データ'!C25 | E8: ='①入力データ'!I40*'①入力データ'!B57 | F8: ― | G8: ='①入力データ'!C10 | H8: =C8+D8+E8-G8 | I8: ='①入力データ'!C11/30 | J8: =IF(I8>0, H8/I8, 0)
A9: 6月 | B9: 30 | C9: =H8 | D9: ='①入力データ'!C26 | E9: ='①入力データ'!I41*'①入力データ'!B57 | F9: ― | G9: ='①入力データ'!C11 | H9: =C9+D9+E9-G9 | I9: ='①入力データ'!C12/31 | J9: =IF(I9>0, H9/I9, 0)
A10: 7月 | B10: 31 | C10: =H9 | D10: ='①入力データ'!C27 | E10: ='①入力データ'!I42*'①入力データ'!B57 | F10: ― | G10: ='①入力データ'!C12 | H10: =C10+D10+E10-G10 | I10: ='①入力データ'!C13/31 | J10: =IF(I10>0, H10/I10, 0)
A11: 8月 | B11: 31 | C11: =H10 | D11: ='①入力データ'!C28 | E11: ='①入力データ'!I43*'①入力データ'!B57 | F11: ― | G11: ='①入力データ'!C13 | H11: =C11+D11+E11-G11 | I11: ='①入力データ'!C14/30 | J11: =IF(I11>0, H11/I11, 0)
A12: 9月 | B12: 30 | C12: =H11 | D12: ='①入力データ'!C29 | E12: ='①入力データ'!I44*'①入力データ'!B57 | F12: ― | G12: ='①入力データ'!C14 | H12: =C12+D12+E12-G12 | I12: ='①入力データ'!C15/31 | J12: =IF(I12>0, H12/I12, 0)
A13: 10月 | B13: 31 | C13: =H12 | D13: ='①入力データ'!C30 | E13: ='①入力データ'!I45*'①入力データ'!B57 | F13: ― | G13: ='①入力データ'!C15 | H13: =C13+D13+E13-G13 | I13: ='①入力データ'!C16/30 | J13: =IF(I13>0, H13/I13, 0)
A14: 11月 | B14: 30 | C14: =H13 | D14: ='①入力データ'!C31 | E14: ='①入力データ'!I46*'①入力データ'!B57 | F14: ― | G14: ='①入力データ'!C16 | H14: =C14+D14+E14-G14 | I14: ='①入力データ'!C17/31 | J14: =IF(I14>0, H14/I14, 0)
A15: 12月 | B15: 31 | C15: =H14 | D15: ='①入力データ'!C32 | E15: ='①入力データ'!I47*'①入力データ'!B57 | F15: ― | G15: ='①入力データ'!C17 | H15: =C15+D15+E15-G15 | I15: ='①入力データ'!C17/31 | J15: =IF(I15>0, H15/I15, 0)

Sheet ④CH3_B2B
A1: 在庫・DOS予測 ― CH3 B2B
A2: ※ 月初在庫：1月は入力データシートの実績値を参照 2月以降は前月末在庫を自動引継ぎ
A3: 月 | B3: 当月日数 | C3: 月初在庫 | D3: 仕入 | E3: （調整なし） | F3: （調整なし） | G3: 当月売上 | H3: 月末在庫 | I3: 翌月日販 | J3: DOS（日）
A4: 1月 | B4: 31 | C4: ='①入力データ'!B54 | D4: ='①入力データ'!D21 | E4: ― | F4: ― | G4: ='①入力データ'!D6 | H4: =C4+D4-G4 | I4: ='①入力データ'!D7/28 | J4: =IF(I4>0, H4/I4, 0)
A5: 2月 | B5: 28 | C5: ='①入力データ'!B55 | D5: ='①入力データ'!D22 | E5: ― | F5: ― | G5: ='①入力データ'!D7 | H5: =C5+D5-G5 | I5: ='①入力データ'!D8/31 | J5: =IF(I5>0, H5/I5, 0)
A6: 3月 | B6: 31 | C6: =H5 | D6: ='①入力データ'!D23 | E6: ― | F6: ― | G6: ='①入力データ'!D8 | H6: =C6+D6-G6 | I6: ='①入力データ'!D9/30 | J6: =IF(I6>0, H6/I6, 0)
A7: 4月 | B7: 30 | C7: =H6 | D7: ='①入力データ'!D24 | E7: ― | F7: ― | G7: ='①入力データ'!D9 | H7: =C7+D7-G7 | I7: ='①入力データ'!D10/31 | J7: =IF(I7>0, H7/I7, 0)
A8: 5月 | B8: 31 | C8: =H7 | D8: ='①入力データ'!D25 | E8: ― | F8: ― | G8: ='①入力データ'!D10 | H8: =C8+D8-G8 | I8: ='①入力データ'!D11/30 | J8: =IF(I8>0, H8/I8, 0)
A9: 6月 | B9: 30 | C9: =H8 | D9: ='①入力データ'!D26 | E9: ― | F9: ― | G9: ='①入力データ'!D11 | H9: =C9+D9-G9 | I9: ='①入力データ'!D12/31 | J9: =IF(I9>0, H9/I9, 0)
A10: 7月 | B10: 31 | C10: =H9 | D10: ='①入力データ'!D27 | E10: ― | F10: ― | G10: ='①入力データ'!D12 | H10: =C10+D10-G10 | I10: ='①入力データ'!D13/31 | J10: =IF(I10>0, H10/I10, 0)
A11: 8月 | B11: 31 | C11: =H10 | D11: ='①入力データ'!D28 | E11: ― | F11: ― | G11: ='①入力データ'!D13 | H11: =C11+D11-G11 | I11: ='①入力データ'!D14/30 | J11: =IF(I11>0, H11/I11, 0)
A12: 9月 | B12: 30 | C12: =H11 | D12: ='①入力データ'!D29 | E12: ― | F12: ― | G12: ='①入力データ'!D14 | H12: =C12+D12-G12 | I12: ='①入力データ'!D15/31 | J12: =IF(I12>0, H12/I12, 0)
A13: 10月 | B13: 31 | C13: =H12 | D13: ='①入力データ'!D30 | E13: ― | F13: ― | G13: ='①入力データ'!D15 | H13: =C13+D13-G13 | I13: ='①入力データ'!D16/30 | J13: =IF(I13>0, H13/I13, 0)
A14: 11月 | B14: 30 | C14: =H13 | D14: ='①入力データ'!D31 | E14: ― | F14: ― | G14: ='①入力データ'!D16 | H14: =C14+D14-G14 | I14: ='①入力データ'!D17/31 | J14: =IF(I14>0, H14/I14, 0)
A15: 12月 | B15: 31 | C15: =H14 | D15: ='①入力データ'!D32 | E15: ― | F15: ― | G15: ='①入力データ'!D17 | H15: =C15+D15-G15 | I15: ='①入力データ'!D17/31 | J15: =IF(I15>0, H15/I15, 0)

Sheet ⑤サマリ（合計）
A1: 在庫金額・DOS 月次推移サマリ （全チャネル合計）
A2: 月 | B2: CH1売上 | C2: CH2売上 | D2: CH3売上 | E2: 合計売上 | F2: CH1月末在庫 | G2: CH2月末在庫 | H2: CH3月末在庫 | I2: 合計在庫 | J2: CH1 DOS | K2: CH2 DOS | L2: CH3 DOS | M2: 合計 DOS
A3: 1月 | B3: ='②CH1_店舗'!G4 | C3: ='③CH2_ROBO'!G4 | D3: ='④CH3_B2B'!G4 | E3: =B3+C3+D3 | F3: ='②CH1_店舗'!H4 | G3: ='③CH2_ROBO'!H4 | H3: ='④CH3_B2B'!H4 | I3: =F3+G3+H3 | J3: ='②CH1_店舗'!J4 | K3: ='③CH2_ROBO'!J4 | L3: ='④CH3_B2B'!J4 | M3: =IF(('①入力データ'!E7/28)>0, I3/('①入力データ'!E7/28), 0)
A4: 2月 | B4: ='②CH1_店舗'!G5 | C4: ='③CH2_ROBO'!G5 | D4: ='④CH3_B2B'!G5 | E4: =B4+C4+D4 | F4: ='②CH1_店舗'!H5 | G4: ='③CH2_ROBO'!H5 | H4: ='④CH3_B2B'!H5 | I4: =F4+G4+H4 | J4: ='②CH1_店舗'!J5 | K4: ='③CH2_ROBO'!J5 | L4: ='④CH3_B2B'!J5 | M4: =IF(('①入力データ'!E8/31)>0, I4/('①入力データ'!E8/31), 0)
A5: 3月 | B5: ='②CH1_店舗'!G6 | C5: ='③CH2_ROBO'!G6 | D5: ='④CH3_B2B'!G6 | E5: =B5+C5+D5 | F5: ='②CH1_店舗'!H6 | G5: ='③CH2_ROBO'!H6 | H5: ='④CH3_B2B'!H6 | I5: =F5+G5+H5 | J5: ='②CH1_店舗'!J6 | K5: ='③CH2_ROBO'!J6 | L5: ='④CH3_B2B'!J6 | M5: =IF(('①入力データ'!E9/30)>0, I5/('①入力データ'!E9/30), 0)
A6: 4月 | B6: ='②CH1_店舗'!G7 | C6: ='③CH2_ROBO'!G7 | D6: ='④CH3_B2B'!G7 | E6: =B6+C6+D6 | F6: ='②CH1_店舗'!H7 | G6: ='③CH2_ROBO'!H7 | H6: ='④CH3_B2B'!H7 | I6: =F6+G6+H6 | J6: ='②CH1_店舗'!J7 | K6: ='③CH2_ROBO'!J7 | L6: ='④CH3_B2B'!J7 | M6: =IF(('①入力データ'!E10/31)>0, I6/('①入力データ'!E10/31), 0)
A7: 5月 | B7: ='②CH1_店舗'!G8 | C7: ='③CH2_ROBO'!G8 | D7: ='④CH3_B2B'!G8 | E7: =B7+C7+D7 | F7: ='②CH1_店舗'!H8 | G7: ='③CH2_ROBO'!H8 | H7: ='④CH3_B2B'!H8 | I7: =F7+G7+H7 | J7: ='②CH1_店舗'!J8 | K7: ='③CH2_ROBO'!J8 | L7: ='④CH3_B2B'!J8 | M7: =IF(('①入力データ'!E11/30)>0, I7/('①入力データ'!E11/30), 0)
A8: 6月 | B8: ='②CH1_店舗'!G9 | C8: ='③CH2_ROBO'!G9 | D8: ='④CH3_B2B'!G9 | E8: =B8+C8+D8 | F8: ='②CH1_店舗'!H9 | G8: ='③CH2_ROBO'!H9 | H8: ='④CH3_B2B'!H9 | I8: =F8+G8+H8 | J8: ='②CH1_店舗'!J9 | K8: ='③CH2_ROBO'!J9 | L8: ='④CH3_B2B'!J9 | M8: =IF(('①入力データ'!E12/31)>0, I8/('①入力データ'!E12/31), 0)
A9: 7月 | B9: ='②CH1_店舗'!G10 | C9: ='③CH2_ROBO'!G10 | D9: ='④CH3_B2B'!G10 | E9: =B9+C9+D9 | F9: ='②CH1_店舗'!H10 | G9: ='③CH2_ROBO'!H10 | H9: ='④CH3_B2B'!H10 | I9: =F9+G9+H9 | J9: ='②CH1_店舗'!J10 | K9: ='③CH2_ROBO'!J10 | L9: ='④CH3_B2B'!J10 | M9: =IF(('①入力データ'!E13/31)>0, I9/('①入力データ'!E13/31), 0)
A10: 8月 | B10: ='②CH1_店舗'!G11 | C10: ='③CH2_ROBO'!G11 | D10: ='④CH3_B2B'!G11 | E10: =B10+C10+D10 | F10: ='②CH1_店舗'!H11 | G10: ='③CH2_ROBO'!H11 | H10: ='④CH3_B2B'!H11 | I10: =F10+G10+H10 | J10: ='②CH1_店舗'!J11 | K10: ='③CH2_ROBO'!J11 | L10: ='④CH3_B2B'!J11 | M10: =IF(('①入力データ'!E14/30)>0, I10/('①入力データ'!E14/30), 0)
A11: 9月 | B11: ='②CH1_店舗'!G12 | C11: ='③CH2_ROBO'!G12 | D11: ='④CH3_B2B'!G12 | E11: =B11+C11+D11 | F11: ='②CH1_店舗'!H12 | G11: ='③CH2_ROBO'!H12 | H11: ='④CH3_B2B'!H12 | I11: =F11+G11+H11 | J11: ='②CH1_店舗'!J12 | K11: ='③CH2_ROBO'!J12 | L11: ='④CH3_B2B'!J12 | M11: =IF(('①入力データ'!E15/31)>0, I11/('①入力データ'!E15/31), 0)
A12: 10月 | B12: ='②CH1_店舗'!G13 | C12: ='③CH2_ROBO'!G13 | D12: ='④CH3_B2B'!G13 | E12: =B12+C12+D12 | F12: ='②CH1_店舗'!H13 | G12: ='③CH2_ROBO'!H13 | H12: ='④CH3_B2B'!H13 | I12: =F12+G12+H12 | J12: ='②CH1_店舗'!J13 | K12: ='③CH2_ROBO'!J13 | L12: ='④CH3_B2B'!J13 | M12: =IF(('①入力データ'!E16/30)>0, I12/('①入力データ'!E16/30), 0)
A13: 11月 | B13: ='②CH1_店舗'!G14 | C13: ='③CH2_ROBO'!G14 | D13: ='④CH3_B2B'!G14 | E13: =B13+C13+D13 | F13: ='②CH1_店舗'!H14 | G13: ='③CH2_ROBO'!H14 | H13: ='④CH3_B2B'!H14 | I13: =F13+G13+H13 | J13: ='②CH1_店舗'!J14 | K13: ='③CH2_ROBO'!J14 | L13: ='④CH3_B2B'!J14 | M13: =IF(('①入力データ'!E17/31)>0, I13/('①入力データ'!E17/31), 0)
A14: 12月 | B14: ='②CH1_店舗'!G15 | C14: ='③CH2_ROBO'!G15 | D14: ='④CH3_B2B'!G15 | E14: =B14+C14+D14 | F14: ='②CH1_店舗'!H15 | G14: ='③CH2_ROBO'!H15 | H14: ='④CH3_B2B'!H15 | I14: =F14+G14+H14 | J14: ='②CH1_店舗'!J15 | K14: ='③CH2_ROBO'!J15 | L14: ='④CH3_B2B'!J15 | M14: =IF(('①入力データ'!E17/31)>0, I14/('①入力データ'!E17/31), 0)
A15: 年間合計 | B15: =SUM(B3:B14) | C15: =SUM(C3:C14) | D15: =SUM(D3:D14) | E15: =SUM(E3:E14) | F15: ― | G15: ― | H15: ― | I15: ― | J15: ― | K15: ― | L15: ― | M15: ―
